Workbook

Sheet Data
C1: Employee Data
C5: Name | D5: Gender | E5: Department | F5: Age | G5: Date Joined | H5: Salary | I5: Rating | J5: Country
C6: Lindy Guillet | D6: Male | E6: Sales | F6: 22 | G6: 44446 | H6: 112780 | I6: Above average | J6: ="NZ" -> NZ
C7: Ambros Murthwaite | D7: Male | E7: Procurement | F7: 46 | G7: 44758 | H7: 70610 | I7: Average | J7: ="NZ" -> NZ
C8: Tatum Hush | D8: Female | E8: Sales | F8: 28 | G8: 44357 | H8: 53240 | I8: Average | J8: ="NZ" -> NZ
C9: Benny Karolovsky | E9: Finance | F9: 37 | G9: 44146 | H9: 115440 | I9: Poor | J9: ="NZ" -> NZ
C10: Hoyt D'Alesco | D10: Male | E10: Sales | F10: 32 | G10: 44465 | H10: 53540 | I10: Average | J10: ="NZ" -> NZ
C11: Halimeda Kuscha | D11: Female | E11: Procurement | F11: 30 | G11: 44861 | H11: 112570 | I11: Average | J11: ="NZ" -> NZ
C12: Erin Androsik | D12: Male | E12: Procurement | F12: 33 | G12: 44701 | H12: 48530 | I12: Above average | J12: ="NZ" -> NZ
C13: Vic Radolf | D13: Female | E13: Website | F13: 24 | G13: 44148 | H13: 62780 | I13: Average | J13: ="NZ" -> NZ
C14: William Reeveley | D14: Male | E14: Website | F14: 33 | G14: 44509 | H14: 53870 | I14: Average | J14: ="NZ" -> NZ
C15: Ewart Laphorn | D15: Female | E15: HR | F15: 27 | G15: 44122 | H15: 119110 | I15: Average | J15: ="NZ" -> NZ
C16: Bev Lashley | D16: Male | E16: Website | F16: 29 | G16: 44180 | H16: 112110 | I16: Poor | J16: ="NZ" -> NZ
C17: Kath Bletsoe | D17: Male | E17: Sales | F17: 25 | G17: 44383 | H17: 65700 | I17: Average | J17: ="NZ" -> NZ
C18: Murry Dryburgh | D18: Male | E18: Website | F18: 37 | G18: 44701 | H18: 69070 | I18: Average | J18: ="NZ" -> NZ
C19: Kaine Padly | D19: Male | E19: Website | F19: 20 | G19: 44459 | H19: 107700 | I19: Average | J19: ="NZ" -> NZ
C20: Kassi Jonson | D20: Female | E20: Website | F20: 32 | G20: 44354 | H20: 43840 | I20: Above average | J20: ="NZ" -> NZ
C21: Simon Kembery | D21: Male | E21: Procurement | F21: 40 | G21: 44263 | H21: 99750 | I21: Average | J21: ="NZ" -> NZ
... C29: Esmaria Denecamp | D29: Male | E29: Finance | F29: 27 | G29: 44567 | H29: 48980 | I29: Average | J29: ="NZ" -> NZ
C30: Curtice Advani | E30: Finance | F30: 30 | G30: 44597 | H30: 64000 | I30: Average | J30: ="NZ" -> NZ
C31: Barr Faughny | D31: Female | E31: Procurement | F31: 42 | G31: 44779 | H31: 75000 | I31: Exceptional | J31: ="NZ" -> NZ
C32: Merrilee Plenty | D32: Female | E32: Website | F32: 40 | G32: 44337 | H32: 87620 | I32: Average | J32: ="NZ" -> NZ
C33: Niall Selesnick | D33: Female | E33: Website | F33: 29 | G33: 44023 | H33: 34980 | I33: Average | J33: ="NZ" -> NZ
C34: Beverie Moffet | D34: Female | E34: Finance | F34: 28 | G34: 44185 | H34: 75970 | I34: Average | J34: ="NZ" -> NZ
C35: Jehu Rudeforth | D35: Female | E35: Finance | F35: 34 | G35: 44612 | H35: 60130 | I35: Average | J35: ="NZ" -> NZ
C36: Camilla Castle | D36: Female | E36: Website | F36: 33 | G36: 44374 | H36: 75480 | I36: Very poor | J36: ="NZ" -> NZ
C37: Roddy Speechley | D37: Male | E37: Procurement | F37: 33 | G37: 44164 | H37: 115920 | I37: Average | J37: ="NZ" -> NZ
C38: Gray Seamon | D38: Female | E38: Sales | F38: 36 | G38: 44494 | H38: 78540 | I38: Average | J38: ="NZ" -> NZ
C39: Madelene Upcott | D39: Male | E39: Procurement | F39: 25 | G39: 44726 | H39: 109190 | I39: Above average | J39: ="NZ" -> NZ
C40: Violante Courtonne | D40: Female | E40: Sales | F40: 34 | G40: 44721 | H40: 49630 | I40: Poor | J40: ="NZ" -> NZ
C41: Bernie Gorges | D41: Female | E41: Procurement | F41: 28 | G41: 44630 | H41: 99970 | I41: Average | J41: ="NZ" -> NZ
C42: Torrance Collier | D42: Female | E42: Website | F42: 33 | G42: 44190 | H42: 96140 | I42: Average | J42: ="NZ" -> NZ
... C67: Wilone O'Kielt | D67: Female | E67: Website | F67: 43 | G67: 45045 | H67: 114870 | I67: Average | J67: ="NZ" -> NZ
C68: Madge McCloughen | E68: Website | F68: 32 | G68: 44774 | H68: 91310 | I68: Average | J68: ="NZ" -> NZ
C69: Janene Hairsine | D69: Female | E69: Procurement | F69: 28 | G69: 44486 | H69: 104770 | I69: Average | J69: ="NZ" -> NZ
C70: Alta Kaszper | D70: Male | E70: Sales | F70: 27 | G70: 44134 | H70: 54970 | I70: Average | J70: ="NZ" -> NZ
C71: Dennison Crosswaite | E71: Website | F71: 26 | G71: 44271 | H71: 90700 | I71: Above average | J71: ="NZ" -> NZ
C72: Oran Buxcy | D72: Female | E72: Sales | F72: 38 | G72: 44329 | H72: 56870 | I72: Above average | J72: ="NZ" -> NZ
C73: Hinda Label | D73: Female | E73: Sales | F73: 25 | G73: 44205 | H73: 92700 | I73: Average | J73: ="NZ" -> NZ
C74: Marney O'Breen | D74: Female | E74: Finance | F74: 21 | G74: 44317 | H74: 65920 | I74: Average | J74: ="NZ" -> NZ
...

Sheet India Staff
B2: Name | C2: Gender | D2: Department | E2: Age | F2: Date Joined | G2: Salary | H2: Rating | I2: Country | J2: Year | K2: Month_num | L2: Month_name
B3: Heer Pennathur | C3: Male | D3: Website | E3: 36 | F3: 43958 | G3: 118840 | H3: Average | I3: ="IND" -> IND | J3: =YEAR(India_staff[[#This Row],[Date Joined]]) -> 2020 | K3: =MONTH(India_staff[[#This Row],[Date Joined]]) -> 5 | L3: =TEXT(India_staff[[#This Row],[Date Joined]],"mmm") -> May
B4: Heer Pennathur | C4: Male | D4: Website | E4: 36 | F4: 43958 | G4: 118840 | H4: Average | I4: ="IND" -> IND | J4: =YEAR(India_staff[[#This Row],[Date Joined]]) -> 2020 | K4: =MONTH(India_staff[[#This Row],[Date Joined]]) -> 5 | L4: =TEXT(India_staff[[#This Row],[Date Joined]],"mmm") -> May
B5: Suchira Bhanupriya Tapti | C5: Female | D5: Website | E5: 29 | F5: 43962 | G5: 34980 | H5: Average | I5: ="IND" -> IND | J5: =YEAR(India_staff[[#This Row],[Date Joined]]) -> 2020 | K5: =MONTH(India_staff[[#This Row],[Date Joined]]) -> 5 | L5: =TEXT(India_staff[[#This Row],[Date Joined]],"mmm") -> May
B6: Ardhendu Abhichandra Jayakar | C6: Male | D6: Finance | E6: 28 | F6: 43980 | G6: 48170 | H6: Above average | I6: ="IND" -> IND | J6: =YEAR(India_staff[[#This Row],[Date Joined]]) -> 2020 | K6: =MONTH(India_staff[[#This Row],[Date Joined]]) -> 5 | L6: =TEXT(India_staff[[#This Row],[Date Joined]],"mmm") -> May
B7: Ardhendu Abhichandra Jayakar | C7: Male | D7: Finance | E7: 28 | F7: 43980 | G7: 48170 | H7: Above average | I7: ="IND" -> IND | J7: =YEAR(India_staff[[#This Row],[Date Joined]]) -> 2020 | K7: =MONTH(India_staff[[#This Row],[Date Joined]]) -> 5 | L7: =TEXT(India_staff[[#This Row],[Date Joined]],"mmm") -> May
B8: Kevalkumar Solanki | C8: Female | D8: Finance | E8: 33 | F8: 44006 | G8: 65360 | H8: Average | I8: ="IND" -> IND | J8: =YEAR(India_staff[[#This Row],[Date Joined]]) -> 2020 | K8: =MONTH(India_staff[[#This Row],[Date Joined]]) -> 6 | L8: =TEXT(India_staff[[#This Row],[Date Joined]],"mmm") -> Jun
B9: Dhruv Manjunath | C9: Female | D9: Procurement | E9: 36 | F9: 44023 | G9: 114890 | H9: Average | I9: ="IND" -> IND | J9: =YEAR(India_staff[[#This Row],[Date Joined]]) -> 2020 | K9: =MONTH(India_staff[[#This Row],[Date Joined]]) -> 7 | L9: =TEXT(India_staff[[#This Row],[Date Joined]],"mmm") -> Jul
B10: Akbar Sorabhjee | C10: Male | D10: Procurement | E10: 21 | F10: 44042 | G10: 37920 | H10: Average | I10: ="IND" -> IND | J10: =YEAR(India_staff[[#This Row],[Date Joined]]) -> 2020 | K10: =MONTH(India_staff[[#This Row],[Date Joined]]) -> 7 | L10: =TEXT(India_staff[[#This Row],[Date Joined]],"mmm") -> Jul
B11: Akbar Sorabhjee | C11: Male | D11: Procurement | E11: 21 | F11: 44042 | G11: 37920 | H11: Average | I11: ="IND" -> IND | J11: =YEAR(India_staff[[#This Row],[Date Joined]]) -> 2020 | K11: =MONTH(India_staff[[#This Row],[Date Joined]]) -> 7 | L11: =TEXT(India_staff[[#This Row],[Date Joined]],"mmm") -> Jul
B12: Anjushri Chandiramani | C12: Female | D12: HR | E12: 27 | F12: 44061 | G12: 119110 | H12: Average | I12: ="IND" -> IND | J12: =YEAR(India_staff[[#This Row],[Date Joined]]) -> 2020 | K12: =MONTH(India_staff[[#This Row],[Date Joined]]) -> 8 | L12: =TEXT(India_staff[[#This Row],[Date Joined]],"mmm") -> Aug
B13: Sanchali Shirish | C13: Male | D13: Sales | E13: 27 | F13: 44073 | G13: 54970 | H13: Average | I13: ="IND" -> IND | J13: =YEAR(India_staff[[#This Row],[Date Joined]]) -> 2020 | K13: =MONTH(India_staff[[#This Row],[Date Joined]]) -> 8 | L13: =TEXT(India_staff[[#This Row],[Date Joined]],"mmm") -> Aug
B14: Jagajeet Viraj | C14: Female | D14: Website | E14: 31 | F14: 44084 | G14: 41980 | H14: Average | I14: ="IND" -> IND | J14: =YEAR(India_staff[[#This Row],[Date Joined]]) -> 2020 | K14: =MONTH(India_staff[[#This Row],[Date Joined]]) -> 9 | L14: =TEXT(India_staff[[#This Row],[Date Joined]],"mmm") -> Sep
B15: Sahila Chandrasekhar | D15: Finance | E15: 37 | F15: 44085 | G15: 115440 | H15: Poor | I15: ="IND" -> IND | J15: =YEAR(India_staff[[#This Row],[Date Joined]]) -> 2020 | K15: =MONTH(India_staff[[#This Row],[Date Joined]]) -> 9 | L15: =TEXT(India_staff[[#This Row],[Date Joined]],"mmm") -> Sep
B16: Sahila Chandrasekhar | D16: Finance | E16: 37 | F16: 44085 | G16: 115440 | H16: Poor | I16: ="IND" -> IND | J16: =YEAR(India_staff[[#This Row],[Date Joined]]) -> 2020 | K16: =MONTH(India_staff[[#This Row],[Date Joined]]) -> 9 | L16: =TEXT(India_staff[[#This Row],[Date Joined]],"mmm") -> Sep
B17: Fullara Sushanti Mokate | C17: Female | D17: Website | E17: 24 | F17: 44087 | G17: 62780 | H17: Average | I17: ="IND" -> IND | J17: =YEAR(India_staff[[#This Row],[Date Joined]]) -> 2020 | K17: =MONTH(India_staff[[#This Row],[Date Joined]]) -> 9 | L17: =TEXT(India_staff[[#This Row],[Date Joined]],"mmm") -> Sep
B18: Sarayu Ragunathan | C18: Male | D18: Procurement | E18: 33 | F18: 44103 | G18: 115920 | H18: Average | I18: ="IND" -> IND | J18: =YEAR(India_staff[[#This Row],[Date Joined]]) -> 2020 | K18: =MONTH(India_staff[[#This Row],[Date Joined]]) -> 9 | L18: =TEXT(India_staff[[#This Row],[Date Joined]],"mmm") -> Sep
B19: Narois Motiwala | C19: Male | D19: Website | E19: 29 | F19: 44119 | G19: 112110 | H19: Poor | I19: ="IND" -> IND | J19: =YEAR(India_staff[[#This Row],[Date Joined]]) -> 2020 | K19: =MONTH(India_staff[[#This Row],[Date Joined]]) -> 10 | L19: =TEXT(India_staff[[#This Row],[Date Joined]],"mmm") -> Oct
B20: Deepali Charan | C20: Male | D20: Website | E20: 20 | F20: 44122 | G20: 112650 | H20: Average | I20: ="IND" -> IND | J20: =YEAR(India_staff[[#This Row],[Date Joined]]) -> 2020 | K20: =MONTH(India_staff[[#This Row],[Date Joined]]) -> 10 | L20: =TEXT(India_staff[[#This Row],[Date Joined]],"mmm") -> Oct
B21: Deepali Charan | C21: Male | D21: Website | E21: 20 | F21: 44122 | G21: 112650 | H21: Average | I21: ="IND" -> IND | J21: =YEAR(India_staff[[#This Row],[Date Joined]]) -> 2020 | K21: =MONTH(India_staff[[#This Row],[Date Joined]]) -> 10 | L21: =TEXT(India_staff[[#This Row],[Date Joined]],"mmm") -> Oct
B22: Indu Varada Sumedh | C22: Female | D22: Finance | E22: 28 | F22: 44124 | G22: 75970 | H22: Average | I22: ="IND" -> IND | J22: =YEAR(India_staff[[#This Row],[Date Joined]]) -> 2020 | K22: =MONTH(India_staff[[#This Row],[Date Joined]]) -> 10 | L22: =TEXT(India_staff[[#This Row],[Date Joined]],"mmm") -> Oct
B23: Sukhdev Nageshwar | C23: Female | D23: Website | E23: 33 | F23: 44129 | G23: 96140 | H23: Average | I23: ="IND" -> IND | J23: =YEAR(India_staff[[#This Row],[Date Joined]]) -> 2020 | K23: =MONTH(India_staff[[#This Row],[Date Joined]]) -> 10 | L23: =TEXT(India_staff[[#This Row],[Date Joined]],"mmm") -> Oct
B24: Purnendu Vijayarangan | C24: Female | D24: Sales | E24: 25 | F24: 44144 | G24: 92700 | H24: Average | I24: ="IND" -> IND | J24: =YEAR(India_staff[[#This Row],[Date Joined]]) -> 2020 | K24: =MONTH(India_staff[[#This Row],[Date Joined]]) -> 11 | L24: =TEXT(India_staff[[#This Row],[Date Joined]],"mmm") -> Nov
B25: Purnendu Vijayarangan | C25: Female | D25: Sales | E25: 25 | F25: 44144 | G25: 92700 | H25: Average | I25: ="IND" -> IND | J25: =YEAR(India_staff[[#This Row],[Date Joined]]) -> 2020 | K25: =MONTH(India_staff[[#This Row],[Date Joined]]) -> 11 | L25: =TEXT(India_staff[[#This Row],[Date Joined]],"mmm") -> Nov
B26: Shiuli Sapna | C26: Male | D26: Procurement | E26: 26 | F26: 44164 | G26: 47360 | H26: Average | I26: ="IND" -> IND | J26: =YEAR(India_staff[[#This Row],[Date Joined]]) -> 2020 | K26: =MONTH(India_staff[[#This Row],[Date Joined]]) -> 11 | L26: =TEXT(India_staff[[#This Row],[Date Joined]],"mmm") -> Nov
B27: Kamalakshi Mukundan | C27: Male | D27: Finance | E27: 27 | F27: 44174 | G27: 91650 | H27: Above average | I27: ="IND" -> IND | J27: =YEAR(India_staff[[#This Row],[Date Joined]]) -> 2020 | K27: =MONTH(India_staff[[#This Row],[Date Joined]]) -> 12 | L27: =TEXT(India_staff[[#This Row],[Date Joined]],"mmm") -> Dec
B28: Sameer Shashank Sapra | C28: Male | D28: HR | E28: 21 | F28: 44180 | G28: 75880 | H28: Average | I28: ="IND" -> IND | J28: =YEAR(India_staff[[#This Row],[Date Joined]]) -> 2020 | K28: =MONTH(India_staff[[#This Row],[Date Joined]]) -> 12 | L28: =TEXT(India_staff[[#This Row],[Date Joined]],"mmm") -> Dec
... B30: Baruna Ogale | C30: Male | D30: Procurement | E30: 40 | F30: 44204 | G30: 99750 | H30: Average | I30: ="IND" -> IND | J30: =YEAR(India_staff[[#This Row],[Date Joined]]) -> 2021 | K30: =MONTH(India_staff[[#This Row],[Date Joined]]) -> 1 | L30: =TEXT(India_staff[[#This Row],[Date Joined]],"mmm") -> Jan
B31: Karuna Pashupathy | D31: Website | E31: 27 | F31: 44212 | G31: 90700 | H31: Above average | I31: ="IND" -> IND | J31: =YEAR(India_staff[[#This Row],[Date Joined]]) -> 2021 | K31: =MONTH(India_staff[[#This Row],[Date Joined]]) -> 1 | L31: =TEXT(India_staff[[#This Row],[Date Joined]],"mmm") -> Jan
B32: Rameshwari Chikodi | C32: Male | D32: Website | E32: 30 | F32: 44214 | G32: 69120 | H32: Average | I32: ="IND" -> IND | J32: =YEAR(India_staff[[#This Row],[Date Joined]]) -> 2021 | K32: =MONTH(India_staff[[#This Row],[Date Joined]]) -> 1 | L32: =TEXT(India_staff[[#This Row],[Date Joined]],"mmm") -> Jan
B33: Vinanti Choudhari | C33: Male | D33: Procurement | E33: 19 | F33: 44218 | G33: 58960 | H33: Average | I33: ="IND" -> IND | J33: =YEAR(India_staff[[#This Row],[Date Joined]]) -> 2021 | K33: =MONTH(India_staff[[#This Row],[Date Joined]]) -> 1 | L33: =TEXT(India_staff[[#This Row],[Date Joined]],"mmm") -> Jan
B34: Hemavati Muthiah | C34: Female | D34: Website | E34: 33 | F34: 44253 | G34: 75280 | H34: Average | I34: ="IND" -> IND | J34: =YEAR(India_staff[[#This Row],[Date Joined]]) -> 2021 | K34: =MONTH(India_staff[[#This Row],[Date Joined]]) -> 2 | L34: =TEXT(India_staff[[#This Row],[Date Joined]],"mmm") -> Feb
B35: Agrata Rajarama | C35: Female | D35: Finance | E35: 21 | F35: 44256 | G35: 65920 | H35: Average | I35: ="IND" -> IND | J35: =YEAR(India_staff[[#This Row],[Date Joined]]) -> 2021 | K35: =MONTH(India_staff[[#This Row],[Date Joined]]) -> 3 | L35: =TEXT(India_staff[[#This Row],[Date Joined]],"mmm") -> Mar
B36: Mirium Seemantini Shivakumar | C36: Female | D36: Sales | E36: 38 | F36: 44268 | G36: 56870 | H36: Above average | I36: ="IND" -> IND | J36: =YEAR(India_staff[[#This Row],[Date Joined]]) -> 2021 | K36: =MONTH(India_staff[[#This Row],[Date Joined]]) -> 3 | L36: =TEXT(India_staff[[#This Row],[Date Joined]],"mmm") -> Mar
B37: Mirium Seemantini Shivakumar | C37: Female | D37: Sales | E37: 38 | F37: 44268 | G37: 56870 | H37: Above average | I37: ="IND" -> IND | J37: =YEAR(India_staff[[#This Row],[Date Joined]]) -> 2021 | K37: =MONTH(India_staff[[#This Row],[Date Joined]]) -> 3 | L37: =TEXT(India_staff[[#This Row],[Date Joined]],"mmm") -> Mar
B38: Kulbhushan Moorthy | C38: Male | D38: Finance | E38: 36 | F38: 44272 | G38: 71380 | H38: Average | I38: ="IND" -> IND | J38: =YEAR(India_staff[[#This Row],[Date Joined]]) -> 2021 | K38: =MONTH(India_staff[[#This Row],[Date Joined]]) -> 3 | L38: =TEXT(India_staff[[#This Row],[Date Joined]],"mmm") -> Mar
B39: Godavari Veena | C39: Female | D39: Website | E39: 40 | F39: 44276 | G39: 87620 | H39: Average | I39: ="IND" -> IND | J39: =YEAR(India_staff[[#This Row],[Date Joined]]) -> 2021 | K39: =MONTH(India_staff[[#This Row],[Date Joined]]) -> 3 | L39: =TEXT(India_staff[[#This Row],[Date Joined]],"mmm") -> Mar
B40: Gangadutt Ragha | C40: Male | D40: Website | E40: 37 | F40: 44277 | G40: 88050 | H40: Poor | I40: ="IND" -> IND | J40: =YEAR(India_staff[[#This Row],[Date Joined]]) -> 2021 | K40: =MONTH(India_staff[[#This Row],[Date Joined]]) -> 3 | L40: =TEXT(India_staff[[#This Row],[Date Joined]],"mmm") -> Mar
B41: Yagna Sujeev | C41: Female | D41: Website | E41: 32 | F41: 44293 | G41: 43840 | H41: Above average | I41: ="IND" -> IND | J41: =YEAR(India_staff[[#This Row],[Date Joined]]) -> 2021 | K41: =MONTH(India_staff[[#This Row],[Date Joined]]) -> 4 | L41: =TEXT(India_staff[[#This Row],[Date Joined]],"mmm") -> Apr
B42: Yagna Sujeev | C42: Female | D42: Website | E42: 32 | F42: 44293 | G42: 43840 | H42: Above average | I42: ="IND" -> IND | J42: =YEAR(India_staff[[#This Row],[Date Joined]]) -> 2021 | K42: =MONTH(India_staff[[#This Row],[Date Joined]]) -> 4 | L42: =TEXT(India_staff[[#This Row],[Date Joined]],"mmm") -> Apr
...

Sheet Sheet5
A1: Country | B1: IND | E1: Country | F1: NZ
A3: Department | B3: Count - Name | E3: Department | F3: Count - Name
A4: Procurement | B4: 27 | E4: Procurement | F4: 29
A5: Website | B5: 27 | E5: Website | F5: 27
A6: Finance | B6: 19 | E6: Finance | F6: 19
A7: Sales | B7: 14 | E7: Sales | F7: 14
A8: HR | B8: 4 | E8: HR | F8: 4
A9: Total Result | B9: 91 | E9: Total Result | F9: 93

Sheet All_Staff
B2: Name | C2: Gender | D2: Department | E2: Age | F2: Date Joined | G2: Salary | H2: Rating | I2: Country | J2: Tenure | K2: Bonus | L2: Rating as number | N2: 1 | O2: Count of employees | Q2: =COUNTA(staff[Name]) -> 184
B3: Gretchen Callow | C3: Female | D3: Website | E3: 21 | F3: 44678 | G3: 33920 | H3: Average | I3: ="IND" -> IND | J3: =TODAY()-staff[[#This Row],[Date Joined]] -> 1291 | K3: =ROUNDUP(IF(staff[[#This Row],[Tenure]]>2,3%,2%)*staff[[#This Row],[Salary]],0) -> 1018 | L3: =_xlfn.xlookup(staff[[#This Row],[Rating]],Sheet2!$B$3:$B$7,Sheet2!$C$3:$C$7) -> 3 | O3: Average salary | Q3: =AVERAGE(staff[Salary]) -> 77366.522 | R3: =MEDIAN(G:G) -> 75280
B4: Shubhra Potla | C4: Female | D4: Website | E4: 21 | F4: 44619 | G4: 33920 | H4: Average | I4: NZ | J4: =TODAY()-staff[[#This Row],[Date Joined]] -> 1350 | K4: =ROUNDUP(IF(staff[[#This Row],[Tenure]]>2,3%,2%)*staff[[#This Row],[Salary]],0) -> 1018 | L4: =_xlfn.xlookup(staff[[#This Row],[Rating]],Sheet2!$B$3:$B$7,Sheet2!$C$3:$C$7) -> 3 | O4: Average age | Q4: =AVERAGE(E:E) -> 30.445652 | R4: =MEDIAN(E:E) -> 30
B5: Niall Selesnick | C5: Female | D5: Website | E5: 29 | F5: 44023 | G5: 34980 | H5: Average | I5: ="IND" -> IND | J5: =TODAY()-staff[[#This Row],[Date Joined]] -> 1946 | K5: =ROUNDUP(IF(staff[[#This Row],[Tenure]]>2,3%,2%)*staff[[#This Row],[Salary]],0) -> 1050 | L5: =_xlfn.xlookup(staff[[#This Row],[Rating]],Sheet2!$B$3:$B$7,Sheet2!$C$3:$C$7) -> 3 | O5: Average Tenure | Q5: =AVERAGE(J:J) -> 1534.5
B6: Suchira Bhanupriya Tapti | C6: Female | D6: Website | E6: 29 | F6: 43962 | G6: 34980 | H6: Average | I6: NZ | J6: =TODAY()-staff[[#This Row],[Date Joined]] -> 2007 | K6: =ROUNDUP(IF(staff[[#This Row],[Tenure]]>2,3%,2%)*staff[[#This Row],[Salary]],0) -> 1050 | L6: =_xlfn.xlookup(staff[[#This Row],[Rating]],Sheet2!$B$3:$B$7,Sheet2!$C$3:$C$7) -> 3 | O6: Female ratio %
B7: Bili Sizey | C7: Male | D7: Sales | E7: 43 | F7: 44620 | G7: 36040 | H7: Average | I7: ="IND" -> IND | J7: =TODAY()-staff[[#This Row],[Date Joined]] -> 1349 | K7: =ROUNDUP(IF(staff[[#This Row],[Tenure]]>2,3%,2%)*staff[[#This Row],[Salary]],0) -> 1082 | L7: =_xlfn.xlookup(staff[[#This Row],[Rating]],Sheet2!$B$3:$B$7,Sheet2!$C$3:$C$7) -> 3 | O7: Female count | Q7: =COUNTIFS(staff[Gender],"Female") -> 86
B8: Waheeda Vasuman | C8: Male | D8: Sales | E8: 43 | F8: 44558 | G8: 36040 | H8: Average | I8: NZ | J8: =TODAY()-staff[[#This Row],[Date Joined]] -> 1411 | K8: =ROUNDUP(IF(staff[[#This Row],[Tenure]]>2,3%,2%)*staff[[#This Row],[Salary]],0) -> 1082 | L8: =_xlfn.xlookup(staff[[#This Row],[Rating]],Sheet2!$B$3:$B$7,Sheet2!$C$3:$C$7) -> 3 | O8: Ratio % | Q8: =Q7/184 -> 0.4673913
B9: Orton Livick | C9: Male | D9: Procurement | E9: 21 | F9: 44104 | G9: 37920 | H9: Average | I9: ="IND" -> IND | J9: =TODAY()-staff[[#This Row],[Date Joined]] -> 1865 | K9: =ROUNDUP(IF(staff[[#This Row],[Tenure]]>2,3%,2%)*staff[[#This Row],[Salary]],0) -> 1138 | L9: =_xlfn.xlookup(staff[[#This Row],[Rating]],Sheet2!$B$3:$B$7,Sheet2!$C$3:$C$7) -> 3
B10: Akbar Sorabhjee | C10: Male | D10: Procurement | E10: 21 | F10: 44042 | G10: 37920 | H10: Average | I10: NZ | J10: =TODAY()-staff[[#This Row],[Date Joined]] -> 1927 | K10: =ROUNDUP(IF(staff[[#This Row],[Tenure]]>2,3%,2%)*staff[[#This Row],[Salary]],0) -> 1138 | L10: =_xlfn.xlookup(staff[[#This Row],[Rating]],Sheet2!$B$3:$B$7,Sheet2!$C$3:$C$7) -> 3 | O10: Ratio of 90,000$> | Q10: =COUNTIFS(staff[Salary],">90000") / COUNTA(staff[Salary]) -> 0.34782609
B11: Archibald Filliskirk | C11: Male | D11: Procurement | E11: 35 | F11: 44727 | G11: 40400 | H11: Average | I11: ="IND" -> IND | J11: =TODAY()-staff[[#This Row],[Date Joined]] -> 1242 | K11: =ROUNDUP(IF(staff[[#This Row],[Tenure]]>2,3%,2%)*staff[[#This Row],[Salary]],0) -> 1212 | L11: =_xlfn.xlookup(staff[[#This Row],[Rating]],Sheet2!$B$3:$B$7,Sheet2!$C$3:$C$7) -> 3
B12: Shobhana Samuel | C12: Male | D12: Procurement | E12: 35 | F12: 44666 | G12: 40400 | H12: Average | I12: NZ | J12: =TODAY()-staff[[#This Row],[Date Joined]] -> 1303 | K12: =ROUNDUP(IF(staff[[#This Row],[Tenure]]>2,3%,2%)*staff[[#This Row],[Salary]],0) -> 1212 | L12: =_xlfn.xlookup(staff[[#This Row],[Rating]],Sheet2!$B$3:$B$7,Sheet2!$C$3:$C$7) -> 3 | N12: 2
B13: Crissie Cordel | C13: Female | D13: Procurement | E13: 32 | F13: 44611 | G13: 41570 | H13: Average | I13: ="IND" -> IND | J13: =TODAY()-staff[[#This Row],[Date Joined]] -> 1358 | K13: =ROUNDUP(IF(staff[[#This Row],[Tenure]]>2,3%,2%)*staff[[#This Row],[Salary]],0) -> 1248 | L13: =_xlfn.xlookup(staff[[#This Row],[Rating]],Sheet2!$B$3:$B$7,Sheet2!$C$3:$C$7) -> 3 | O13: Lindy Guillet
B14: Prerana Nishita | C14: Female | D14: Procurement | E14: 32 | F14: 44549 | G14: 41570 | H14: Average | I14: NZ | J14: =TODAY()-staff[[#This Row],[Date Joined]] -> 1420 | K14: =ROUNDUP(IF(staff[[#This Row],[Tenure]]>2,3%,2%)*staff[[#This Row],[Salary]],0) -> 1248 | L14: =_xlfn.xlookup(staff[[#This Row],[Rating]],Sheet2!$B$3:$B$7,Sheet2!$C$3:$C$7) -> 3
B15: Dotty Strutley | C15: Female | D15: Website | E15: 31 | F15: 44145 | G15: 41980 | H15: Average | I15: ="IND" -> IND | J15: =TODAY()-staff[[#This Row],[Date Joined]] -> 1824 | K15: =ROUNDUP(IF(staff[[#This Row],[Tenure]]>2,3%,2%)*staff[[#This Row],[Salary]],0) -> 1260 | L15: =_xlfn.xlookup(staff[[#This Row],[Rating]],Sheet2!$B$3:$B$7,Sheet2!$C$3:$C$7) -> 3 | O15: XLOOKUP
B16: Jagajeet Viraj | C16: Female | D16: Website | E16: 31 | F16: 44084 | G16: 41980 | H16: Average | I16: NZ | J16: =TODAY()-staff[[#This Row],[Date Joined]] -> 1885 | K16: =ROUNDUP(IF(staff[[#This Row],[Tenure]]>2,3%,2%)*staff[[#This Row],[Salary]],0) -> 1260 | L16: =_xlfn.xlookup(staff[[#This Row],[Rating]],Sheet2!$B$3:$B$7,Sheet2!$C$3:$C$7) -> 3 | O16: VLOOKUP
B17: Drusy MacCombe | C17: Male | D17: Sales | E17: 28 | F17: 44820 | G17: 43510 | H17: Very poor | I17: ="IND" -> IND | J17: =TODAY()-staff[[#This Row],[Date Joined]] -> 1149 | K17: =ROUNDUP(IF(staff[[#This Row],[Tenure]]>2,3%,2%)*staff[[#This Row],[Salary]],0) -> 1306 | L17: =_xlfn.xlookup(staff[[#This Row],[Rating]],Sheet2!$B$3:$B$7,Sheet2!$C$3:$C$7) -> 1
B18: Rupak Mehra | C18: Male | D18: Sales | E18: 28 | F18: 44758 | G18: 43510 | H18: Very poor | I18: NZ | J18: =TODAY()-staff[[#This Row],[Date Joined]] -> 1211 | K18: =ROUNDUP(IF(staff[[#This Row],[Tenure]]>2,3%,2%)*staff[[#This Row],[Salary]],0) -> 1306 | L18: =_xlfn.xlookup(staff[[#This Row],[Rating]],Sheet2!$B$3:$B$7,Sheet2!$C$3:$C$7) -> 1 | O18: {=_xlfn.xlookup(O13,staff[Name],staff[[Gender]:[Tenure]])} -> #NAME? | P18: #NAME? | Q18: #NAME? | R18: #NAME? | S18: #NAME? | T18: #NAME? | U18: #NAME? | V18: #NAME?
B19: Kassi Jonson | C19: Female | D19: Website | E19: 32 | F19: 44354 | G19: 43840 | H19: Above average | I19: ="IND" -> IND | J19: =TODAY()-staff[[#This Row],[Date Joined]] -> 1615 | K19: =ROUNDUP(IF(staff[[#This Row],[Tenure]]>2,3%,2%)*staff[[#This Row],[Salary]],0) -> 1316 | L19: =_xlfn.xlookup(staff[[#This Row],[Rating]],Sheet2!$B$3:$B$7,Sheet2!$C$3:$C$7) -> 4
B20: Yagna Sujeev | C20: Female | D20: Website | E20: 32 | F20: 44293 | G20: 43840 | H20: Above average | I20: NZ | J20: =TODAY()-staff[[#This Row],[Date Joined]] -> 1676 | K20: =ROUNDUP(IF(staff[[#This Row],[Tenure]]>2,3%,2%)*staff[[#This Row],[Salary]],0) -> 1316 | L20: =_xlfn.xlookup(staff[[#This Row],[Rating]],Sheet2!$B$3:$B$7,Sheet2!$C$3:$C$7) -> 4 | O20: Gender | P20: {=TRANSPOSE(_xlfn.xlookup(O13,staff[Name],staff[[Gender]:[Tenure]]))} -> #NAME?
B21: Florinda Crace | C21: Female | D21: HR | E21: 32 | F21: 44400 | G21: 45510 | H21: Average | I21: ="IND" -> IND | J21: =TODAY()-staff[[#This Row],[Date Joined]] -> 1569 | K21: =ROUNDUP(IF(staff[[#This Row],[Tenure]]>2,3%,2%)*staff[[#This Row],[Salary]],0) -> 1366 | L21: =_xlfn.xlookup(staff[[#This Row],[Rating]],Sheet2!$B$3:$B$7,Sheet2!$C$3:$C$7) -> 3 | O21: Department | P21: Sales
B22: Madhavdas Buhpathi | C22: Female | D22: HR | E22: 32 | F22: 44339 | G22: 45510 | H22: Average | I22: NZ | J22: =TODAY()-staff[[#This Row],[Date Joined]] -> 1630 | K22: =ROUNDUP(IF(staff[[#This Row],[Tenure]]>2,3%,2%)*staff[[#This Row],[Salary]],0) -> 1366 | L22: =_xlfn.xlookup(staff[[#This Row],[Rating]],Sheet2!$B$3:$B$7,Sheet2!$C$3:$C$7) -> 3 | O22: Age | P22: 22
B23: Dell Molloy | C23: Male | D23: Procurement | E23: 26 | F23: 44225 | G23: 47360 | H23: Average | I23: ="IND" -> IND | J23: =TODAY()-staff[[#This Row],[Date Joined]] -> 1744 | K23: =ROUNDUP(IF(staff[[#This Row],[Tenure]]>2,3%,2%)*staff[[#This Row],[Salary]],0) -> 1421 | L23: =_xlfn.xlookup(staff[[#This Row],[Rating]],Sheet2!$B$3:$B$7,Sheet2!$C$3:$C$7) -> 3 | O23: Date Joined | P23: 44446
B24: Shiuli Sapna | C24: Male | D24: Procurement | E24: 26 | F24: 44164 | G24: 47360 | H24: Average | I24: NZ | J24: =TODAY()-staff[[#This Row],[Date Joined]] -> 1805 | K24: =ROUNDUP(IF(staff[[#This Row],[Tenure]]>2,3%,2%)*staff[[#This Row],[Salary]],0) -> 1421 | L24: =_xlfn.xlookup(staff[[#This Row],[Rating]],Sheet2!$B$3:$B$7,Sheet2!$C$3:$C$7) -> 3 | O24: Salary | P24: 112780
B25: Jan Morforth | C25: Male | D25: Finance | E25: 28 | F25: 44041 | G25: 48170 | H25: Above average | I25: ="IND" -> IND | J25: =TODAY()-staff[[#This Row],[Date Joined]] -> 1928 | K25: =ROUNDUP(IF(staff[[#This Row],[Tenure]]>2,3%,2%)*staff[[#This Row],[Salary]],0) -> 1446 | L25: =_xlfn.xlookup(staff[[#This Row],[Rating]],Sheet2!$B$3:$B$7,Sheet2!$C$3:$C$7) -> 4 | O25: Rating | P25: Above average
B26: Ardhendu Abhichandra Jayakar | C26: Male | D26: Finance | E26: 28 | F26: 43980 | G26: 48170 | H26: Above average | I26: NZ | J26: =TODAY()-staff[[#This Row],[Date Joined]] -> 1989 | K26: =ROUNDUP(IF(staff[[#This Row],[Tenure]]>2,3%,2%)*staff[[#This Row],[Salary]],0) -> 1446 | L26: =_xlfn.xlookup(staff[[#This Row],[Rating]],Sheet2!$B$3:$B$7,Sheet2!$C$3:$C$7) -> 4 | O26: Country | P26: IND
B27: Erin Androsik | C27: Male | D27: Procurement | E27: 33 | F27: 44701 | G27: 48530 | H27: Above average | I27: ="IND" -> IND | J27: =TODAY()-staff[[#This Row],[Date Joined]] -> 1268 | K27: =ROUNDUP(IF(staff[[#This Row],[Tenure]]>2,3%,2%)*staff[[#This Row],[Salary]],0) -> 1456 | L27: =_xlfn.xlookup(staff[[#This Row],[Rating]],Sheet2!$B$3:$B$7,Sheet2!$C$3:$C$7) -> 4 | O27: Tenure | P27: 1522
B28: Piyali Mahanthapa | C28: Male | D28: Procurement | E28: 33 | F28: 44640 | G28: 48530 | H28: Above average | I28: NZ | J28: =TODAY()-staff[[#This Row],[Date Joined]] -> 1329 | K28: =ROUNDUP(IF(staff[[#This Row],[Tenure]]>2,3%,2%)*staff[[#This Row],[Salary]],0) -> 1456 | L28: =_xlfn.xlookup(staff[[#This Row],[Rating]],Sheet2!$B$3:$B$7,Sheet2!$C$3:$C$7) -> 4
B29: Gunar Cockshoot | C29: Male | D29: Website | E29: 31 | F29: 44511 | G29: 48950 | H29: Average | I29: ="IND" -> IND | J29: =TODAY()-staff[[#This Row],[Date Joined]] -> 1458 | K29: =ROUNDUP(IF(staff[[#This Row],[Tenure]]>2,3%,2%)*staff[[#This Row],[Salary]],0) -> 1469 | L29: =_xlfn.xlookup(staff[[#This Row],[Rating]],Sheet2!$B$3:$B$7,Sheet2!$C$3:$C$7) -> 3
B30: Amal Nimesh | C30: Male | D30: Website | E30: 31 | F30: 44450 | G30: 48950 | H30: Average | I30: NZ | J30: =TODAY()-staff[[#This Row],[Date Joined]] -> 1519 | K30: =ROUNDUP(IF(staff[[#This Row],[Tenure]]>2,3%,2%)*staff[[#This Row],[Salary]],0) -> 1469 | L30: =_xlfn.xlookup(staff[[#This Row],[Rating]],Sheet2!$B$3:$B$7,Sheet2!$C$3:$C$7) -> 3
B31: Esmaria Denecamp | C31: Male | D31: Finance | E31: 27 | F31: 44567 | G31: 48980 | H31: Average | I31: ="IND" -> IND | J31: =TODAY()-staff[[#This Row],[Date Joined]] -> 1402 | K31: =ROUNDUP(IF(staff[[#This Row],[Tenure]]>2,3%,2%)*staff[[#This Row],[Salary]],0) -> 1470 | L31: =_xlfn.xlookup(staff[[#This Row],[Rating]],Sheet2!$B$3:$B$7,Sheet2!$C$3:$C$7) -> 3
B32: Vanmala Shriharsha | C32: Male | D32: Finance | E32: 27 | F32: 44506 | G32: 48980 | H32: Average | I32: NZ | J32: =TODAY()-staff[[#This Row],[Date Joined]] -> 1463 | K32: =ROUNDUP(IF(staff[[#This Row],[Tenure]]>2,3%,2%)*staff[[#This Row],[Salary]],0) -> 1470 | L32: =_xlfn.xlookup(staff[[#This Row],[Rating]],Sheet2!$B$3:$B$7,Sheet2!$C$3:$C$7) -> 3
B33: Violante Courtonne | C33: Female | D33: Sales | E33: 34 | F33: 44721 | G33: 49630 | H33: Poor | I33: ="IND" -> IND | J33: =TODAY()-staff[[#This Row],[Date Joined]] -> 1248 | K33: =ROUNDUP(IF(staff[[#This Row],[Tenure]]>2,3%,2%)*staff[[#This Row],[Salary]],0) -> 1489 | L33: =_xlfn.xlookup(staff[[#This Row],[Rating]],Sheet2!$B$3:$B$7,Sheet2!$C$3:$C$7) -> 2
B34: Daruka Ghazali | C34: Female | D34: Sales | E34: 34 | F34: 44660 | G34: 49630 | H34: Poor | I34: NZ | J34: =TODAY()-staff[[#This Row],[Date Joined]] -> 1309 | K34: =ROUNDUP(IF(staff[[#This Row],[Tenure]]>2,3%,2%)*staff[[#This Row],[Salary]],0) -> 1489 | L34: =_xlfn.xlookup(staff[[#This Row],[Rating]],Sheet2!$B$3:$B$7,Sheet2!$C$3:$C$7) -> 2
B35: Kaye Crocroft | C35: Male | D35: Finance | E35: 24 | F35: 44436 | G35: 52610 | H35: Poor | I35: ="IND" -> IND | J35: =TODAY()-staff[[#This Row],[Date Joined]] -> 1533 | K35: =ROUNDUP(IF(staff[[#This Row],[Tenure]]>2,3%,2%)*staff[[#This Row],[Salary]],0) -> 1579 | L35: =_xlfn.xlookup(staff[[#This Row],[Rating]],Sheet2!$B$3:$B$7,Sheet2!$C$3:$C$7) -> 2
B36: Gumwant Veera | C36: Male | D36: Finance | E36: 24 | F36: 44375 | G36: 52610 | H36: Poor | I36: NZ | J36: =TODAY()-staff[[#This Row],[Date Joined]] -> 1594 | K36: =ROUNDUP(IF(staff[[#This Row],[Tenure]]>2,3%,2%)*staff[[#This Row],[Salary]],0) -> 1579 | L36: =_xlfn.xlookup(staff[[#This Row],[Rating]],Sheet2!$B$3:$B$7,Sheet2!$C$3:$C$7) -> 2
B37: Tatum Hush | C37: Female | D37: Sales | E37: 28 | F37: 44357 | G37: 53240 | H37: Average | I37: ="IND" -> IND | J37: =TODAY()-staff[[#This Row],[Date Joined]] -> 1612 | K37: =ROUNDUP(IF(staff[[#This Row],[Tenure]]>2,3%,2%)*staff[[#This Row],[Salary]],0) -> 1598 | L37: =_xlfn.xlookup(staff[[#This Row],[Rating]],Sheet2!$B$3:$B$7,Sheet2!$C$3:$C$7) -> 3
B38: Anumati Shyamari Meherhomji | C38: Female | D38: Sales | E38: 28 | F38: 44296 | G38: 53240 | H38: Average | I38: NZ | J38: =TODAY()-staff[[#This Row],[Date Joined]] -> 1673 | K38: =ROUNDUP(IF(staff[[#This Row],[Tenure]]>2,3%,2%)*staff[[#This Row],[Salary]],0) -> 1598 | L38: =_xlfn.xlookup(staff[[#This Row],[Rating]],Sheet2!$B$3:$B$7,Sheet2!$C$3:$C$7) -> 3
B39: Hoyt D'Alesco | C39: Male | D39: Sales | E39: 32 | F39: 44465 | G39: 53540 | H39: Average | I39: ="IND" -> IND | J39: =TODAY()-staff[[#This Row],[Date Joined]] -> 1504 | K39: =ROUNDUP(IF(staff[[#This Row],[Tenure]]>2,3%,2%)*staff[[#This Row],[Salary]],0) -> 1607 | L39: =_xlfn.xlookup(staff[[#This Row],[Rating]],Sheet2!$B$3:$B$7,Sheet2!$C$3:$C$7) -> 3
B40: Zach Polon | C40: Male | D40: Procurement | E40: 26 | F40: 44411 | G40: 53540 | H40: Average | I40: NZ | J40: =TODAY()-staff[[#This Row],[Date Joined]] -> 1558 | K40: =ROUNDUP(IF(staff[[#This Row],[Tenure]]>2,3%,2%)*staff[[#This Row],[Salary]],0) -> 1607 | L40: =_xlfn.xlookup(staff[[#This Row],[Rating]],Sheet2!$B$3:$B$7,Sheet2!$C$3:$C$7) -> 3
B41: Geena Raghavanpillai | C41: Male | D41: Sales | E41: 32 | F41: 44403 | G41: 53540 | H41: Average | I41: NZ | J41: =TODAY()-staff[[#This Row],[Date Joined]] -> 1566 | K41: =ROUNDUP(IF(staff[[#This Row],[Tenure]]>2,3%,2%)*staff[[#This Row],[Salary]],0) -> 1607 | L41: =_xlfn.xlookup(staff[[#This Row],[Rating]],Sheet2!$B$3:$B$7,Sheet2!$C$3:$C$7) -> 3
...

Sheet Salary spred

Sheet Salary vs. rating

Sheet Info Finder
B2: 3 | C2: Information finder
B5: Departement Name | C5: HR
B7: Number of people | C7: =COUNTIF(staff[Department],C5) -> 8
B9: {=_xlfn._xlws.sort(_xlfn.choosecols(_xlfn._xlws.filter(staff[],staff[Department]=C5),1,6,7),2,-1)} -> #NAME? | C9: #NAME? | D9: #NAME?
B10: #NAME? | C10: #NAME? | D10: #NAME?
B11: #NAME? | C11: #NAME? | D11: #NAME?
B12: #NAME? | C12: #NAME? | D12: #NAME?
B13: #NAME? | C13: #NAME? | D13: #NAME?
B14: #NAME? | C14: #NAME? | D14: #NAME?
B15: #NAME? | C15: #NAME? | D15: #NAME?
B16: #NAME? | C16: #NAME? | D16: #NAME?

Sheet Male vs female
B2: Gender | J2: 4 | K2: Male vs female
A3: Data | B3: Female | C3: Male | D3: Total Result
A4: Count - Name | B4: 86 | C4: 90 | D4: 176
A5: Average - Age | B5: 31.406977 | C5: 29.444444 | D5: 30.403409
A6: Average - Salary | B6: 78284.186 | C6: 75334.444 | D6: 76775.795
A7: Average - Tenure | B7: 1535.907 | C7: 1529.6111 | D7: 1532.6875

Sheet Sheet1
B2: Data
A3: Rating | B3: Count - Name | C3: Average - Salary
A4: Exceptional | B4: 4 | C4: 92080
A5: Above average | B5: 20 | C5: 75933
A6: Average | B6: 138 | C6: 77058.551
A7: Poor | B7: 16 | C7: 78115
A8: Very poor | B8: 6 | C8: 77423.333
A9: Total Result | B9: 184 | C9: 77366.522

Sheet Sheet2
B3: Exceptional | C3: 5
B4: Above average | C4: 4
B5: Average | C5: 3
B6: Poor | C6: 2
B7: Very poor | C7: 1

Sheet Sheet3
A2: Year | B2: Month_name | C2: Count - Name
A3: 2020 | C3: 27
A4: 2021 | B4: Jan | C4: 4
B5: Feb | C5: 1
B6: Mar | C6: 6
B7: Apr | C7: 5
B8: May | C8: 8
B9: Jun | C9: 2
B10: Jul | C10: 9
B11: Aug | C11: 2
B12: Sep | C12: 3
B13: Oct | C13: 1
B14: Nov | C14: 1
B15: Dec | C15: 7
A16: 2021 Result | C16: 49
A17: 2022 | C17: 35
A18: 2023 | B18: Feb | C18: 1
A19: 2023 Result | C19: 1
A20: Total Result | C20: 112

Sheet Sheet4
B2: New Zealand | I2: India
B3: =COUNTIF(staff[Country],"NZ") -> 93 | D3: =COUNTIFS(staff[Country],"NZ",staff[Gender],"Female")/B3 -> 0.46236559 | F3: =AVERAGEIFS(staff[Salary],staff[Country],"NZ") -> 77110.323 | I3: =COUNTIF(staff[Country],"IND") -> 91 | K3: =COUNTIFS(staff[Country],"IND",staff[Gender],"Female")/I3 -> 0.47252747 | M3: =AVERAGEIFS(staff[Salary],staff[Country],"IND") -> 77628.352
B6: Headcount by Department
